<?xml version="1.0"?>
<sdf version="1.9">
  <model name="staubli_tx2_60l_gripper">
    <self_collide>false</self_collide>
    <allow_auto_disable>false</allow_auto_disable>

    <link name="base_link">
      <inertial>
        <pose>-0.03450 0.00021 0.09900 0 0 0</pose>
        <mass>40.0</mass>
        <inertia>
          <ixx>0.60</ixx>
          <iyy>0.60</iyy>
          <izz>0.45</izz>
          <ixy>0</ixy>
          <ixz>0</ixz>
          <iyz>0</iyz>
        </inertia>
      </inertial>
      <visual name="base_link_visual">
        <geometry>
          <mesh>
            <uri>model://staubli_tx2_60l/meshes/tx2_60/visual/base_link.stl</uri>
          </mesh>
        </geometry>
        <material>
          <ambient>0.97 0.74 0.17 1</ambient>
          <diffuse>0.97 0.74 0.17 1</diffuse>
        </material>
      </visual>
      <collision name="base_link_collision">
        <geometry>
          <mesh>
            <uri>model://staubli_tx2_60l/meshes/tx2_60/collision/base_link.stl</uri>
          </mesh>
        </geometry>
      </collision>
    </link>

    <link name="link_1">
      <pose relative_to="joint_1">0 0 0 0 0 0</pose>
      <inertial>
        <pose>-0.00435 0.02003 -0.04881 0 0 0</pose>
        <mass>12.0</mass>
        <inertia>
          <ixx>0.12</ixx>
          <iyy>0.12</iyy>
          <izz>0.10</izz>
          <ixy>0</ixy>
          <ixz>0</ixz>
          <iyz>0</iyz>
        </inertia>
      </inertial>
      <visual name="link_1_visual">
        <geometry>
          <mesh>
            <uri>model://staubli_tx2_60l/meshes/tx2_60/visual/link_1.stl</uri>
          </mesh>
        </geometry>
        <material>
          <ambient>0.97 0.74 0.17 1</ambient>
          <diffuse>0.97 0.74 0.17 1</diffuse>
        </material>
      </visual>
      <collision name="link_1_collision">
        <geometry>
          <mesh>
            <uri>model://staubli_tx2_60l/meshes/tx2_60/collision/link_1.stl</uri>
          </mesh>
        </geometry>
      </collision>
    </link>

    <link name="link_2">
      <pose relative_to="joint_2">0 0 0 0 0 0</pose>
      <inertial>
        <pose>-0.00005 0.17878 0.19222 0 0 0</pose>
        <mass>10.0</mass>
        <inertia>
          <ixx>0.10</ixx>
          <iyy>0.09</iyy>
          <izz>0.08</izz>
          <ixy>0</ixy>
          <ixz>0</ixz>
          <iyz>0</iyz>
        </inertia>
      </inertial>
      <visual name="link_2_visual">
        <geometry>
          <mesh>
            <uri>model://staubli_tx2_60l/meshes/tx2_60l/visual/link_2.stl</uri>
          </mesh>
        </geometry>
        <material>
          <ambient>0.97 0.74 0.17 1</ambient>
          <diffuse>0.97 0.74 0.17 1</diffuse>
        </material>
      </visual>
      <collision name="link_2_collision">
        <geometry>
          <mesh>
            <uri>model://staubli_tx2_60l/meshes/tx2_60l/collision/link_2.stl</uri>
          </mesh>
        </geometry>
      </collision>
    </link>

    <link name="link_3">
      <pose relative_to="joint_3">0 0 0 0 0 0</pose>
      <inertial>
        <pose>0.00071 0.02409 -0.01357 0 0 0</pose>
        <mass>7.0</mass>
        <inertia>
          <ixx>0.07</ixx>
          <iyy>0.06</iyy>
          <izz>0.05</izz>
          <ixy>0</ixy>
          <ixz>0</ixz>
          <iyz>0</iyz>
        </inertia>
      </inertial>
      <visual name="link_3_visual">
        <geometry>
          <mesh>
            <uri>model://staubli_tx2_60l/meshes/tx2_60/visual/link_3.stl</uri>
          </mesh>
        </geometry>
        <material>
          <ambient>0.97 0.74 0.17 1</ambient>
          <diffuse>0.97 0.74 0.17 1</diffuse>
        </material>
      </visual>
      <collision name="link_3_collision">
        <geometry>
          <mesh>
            <uri>model://staubli_tx2_60l/meshes/tx2_60/collision/link_3.stl</uri>
          </mesh>
        </geometry>
      </collision>
    </link>

    <link name="link_4">
      <pose relative_to="joint_4">0 0 0 0 0 0</pose>
      <inertial>
        <pose>-0.01003 0 0.30156 0 0 0</pose>
        <mass>5.0</mass>
        <inertia>
          <ixx>0.04</ixx>
          <iyy>0.04</iyy>
          <izz>0.03</izz>
          <ixy>0</ixy>
          <ixz>0</ixz>
          <iyz>0</iyz>
        </inertia>
      </inertial>
      <visual name="link_4_visual">
        <geometry>
          <mesh>
            <uri>model://staubli_tx2_60l/meshes/tx2_60l/visual/link_4.stl</uri>
          </mesh>
        </geometry>
        <material>
          <ambient>0.97 0.74 0.17 1</ambient>
          <diffuse>0.97 0.74 0.17 1</diffuse>
        </material>
      </visual>
      <collision name="link_4_collision">
        <geometry>
          <mesh>
            <uri>model://staubli_tx2_60l/meshes/tx2_60l/collision/link_4.stl</uri>
          </mesh>
        </geometry>
      </collision>
    </link>

    <link name="link_5">
      <pose relative_to="joint_5">0 0 0 0 0 0</pose>
      <inertial>
        <pose>0 0 0.01378 0 0 0</pose>
        <mass>1.8</mass>
        <inertia>
          <ixx>0.010</ixx>
          <iyy>0.010</iyy>
          <izz>0.008</izz>
          <ixy>0</ixy>
          <ixz>0</ixz>
          <iyz>0</iyz>
        </inertia>
      </inertial>
      <visual name="link_5_visual">
        <geometry>
          <mesh>
            <uri>model://staubli_tx2_60l/meshes/tx60/visual/link_5.stl</uri>
          </mesh>
        </geometry>
        <material>
          <ambient>0.50 0.50 0.50 1</ambient>
          <diffuse>0.50 0.50 0.50 1</diffuse>
        </material>
      </visual>
      <collision name="link_5_collision">
        <geometry>
          <mesh>
            <uri>model://staubli_tx2_60l/meshes/tx60/collision/link_5.stl</uri>
          </mesh>
        </geometry>
      </collision>
    </link>

    <link name="link_6">
      <pose relative_to="joint_6">0 0 0 0 0 0</pose>
      <inertial>
        <pose>0 0 -0.00825 0 0 0</pose>
        <mass>1.0</mass>
        <inertia>
          <ixx>0.004</ixx>
          <iyy>0.004</iyy>
          <izz>0.003</izz>
          <ixy>0</ixy>
          <ixz>0</ixz>
          <iyz>0</iyz>
        </inertia>
      </inertial>
      <visual name="link_6_visual">
        <geometry>
          <mesh>
            <uri>model://staubli_tx2_60l/meshes/tx60/visual/link_6.stl</uri>
          </mesh>
        </geometry>
        <material>
          <ambient>0.50 0.50 0.50 1</ambient>
          <diffuse>0.50 0.50 0.50 1</diffuse>
        </material>
      </visual>
      <collision name="link_6_collision">
        <geometry>
          <mesh>
            <uri>model://staubli_tx2_60l/meshes/tx60/collision/link_6.stl</uri>
          </mesh>
        </geometry>
      </collision>
    </link>

    <link name="flange">
      <pose relative_to="joint_6_flange">0 0 0 0 0 0</pose>
    </link>
    <link name="base">
      <pose relative_to="base_link_base">0 0 0 0 0 0</pose>
    </link>
    <link name="tool0">
      <pose relative_to="flange_tool0">0 0 0 0 0 0</pose>
    </link>
    <link name="gripper_base">
      <pose relative_to="tool0_gripper_base">0 0 0 0 0 0</pose>
      <inertial>
        <mass>0.12</mass>
        <inertia>
          <ixx>0.00003</ixx>
          <iyy>0.00003</iyy>
          <izz>0.00002</izz>
          <ixy>0</ixy>
          <ixz>0</ixz>
          <iyz>0</iyz>
        </inertia>
      </inertial>
      <visual name="gripper_base_visual">
        <geometry>
          <box>
            <size>0.09 0.17 0.03</size>
          </box>
        </geometry>
        <material>
          <ambient>0.50 0.50 0.50 1</ambient>
          <diffuse>0.50 0.50 0.50 1</diffuse>
        </material>
      </visual>
      <collision name="gripper_base_collision">
        <geometry>
          <box>
            <size>0.09 0.17 0.03</size>
          </box>
        </geometry>
      </collision>
    </link>
    <link name="gripper_left_finger">
      <pose relative_to="gripper_left_finger_joint">0 0 0 0 0 0</pose>
      <inertial>
        <mass>0.08</mass>
        <inertia>
          <ixx>0.00003</ixx>
          <iyy>0.00003</iyy>
          <izz>0.00003</izz>
          <ixy>0</ixy>
          <ixz>0</ixz>
          <iyz>0</iyz>
        </inertia>
      </inertial>
      <visual name="gripper_left_finger_visual">
        <geometry>
          <box>
            <size>0.024 0.012 0.09</size>
          </box>
        </geometry>
        <material>
          <ambient>0.01 0.01 0.012 1</ambient>
          <diffuse>0.01 0.01 0.012 1</diffuse>
        </material>
      </visual>
      <collision name="gripper_left_finger_collision">
        <geometry>
          <box>
            <size>0.024 0.012 0.09</size>
          </box>
        </geometry>
      </collision>
    </link>
    <link name="gripper_right_finger">
      <pose relative_to="gripper_right_finger_joint">0 0 0 0 0 0</pose>
      <inertial>
        <mass>0.08</mass>
        <inertia>
          <ixx>0.00003</ixx>
          <iyy>0.00003</iyy>
          <izz>0.00003</izz>
          <ixy>0</ixy>
          <ixz>0</ixz>
          <iyz>0</iyz>
        </inertia>
      </inertial>
      <visual name="gripper_right_finger_visual">
        <geometry>
          <box>
            <size>0.024 0.012 0.09</size>
          </box>
        </geometry>
        <material>
          <ambient>0.01 0.01 0.012 1</ambient>
          <diffuse>0.01 0.01 0.012 1</diffuse>
        </material>
      </visual>
      <collision name="gripper_right_finger_collision">
        <geometry>
          <box>
            <size>0.024 0.012 0.09</size>
          </box>
        </geometry>
      </collision>
    </link>
    <link name="gripper_tcp">
      <pose relative_to="gripper_base_tcp">0 0 0 0 0 0</pose>
    </link>

    <joint name="world_joint" type="fixed">
      <parent>world</parent>
      <child>base_link</child>
    </joint>

    <joint name="joint_1" type="revolute">
      <parent>base_link</parent>
      <child>link_1</child>
      <pose relative_to="base_link">0 0 0.375 0 0 0</pose>
      <axis>
        <xyz>0 0 1</xyz>
        <limit>
          <lower>-3.14159265359</lower>
          <upper>3.14159265359</upper>
          <effort>220.0</effort>
          <velocity>7.59218224618</velocity>
        </limit>
        <dynamics>
          <damping>0.7</damping>
          <friction>0.08</friction>
        </dynamics>
      </axis>
    </joint>

    <joint name="joint_2" type="revolute">
      <parent>link_1</parent>
      <child>link_2</child>
      <pose relative_to="link_1">0 0 0 0 0 0</pose>
      <axis>
        <xyz>0 1 0</xyz>
        <limit>
          <lower>-2.22529479629</lower>
          <upper>2.22529479629</upper>
          <effort>140.0</effort>
          <velocity>6.71951762018</velocity>
        </limit>
        <dynamics>
          <damping>0.7</damping>
          <friction>0.08</friction>
        </dynamics>
      </axis>
    </joint>

    <joint name="joint_3" type="revolute">
      <parent>link_2</parent>
      <child>link_3</child>
      <pose relative_to="link_2">0 0.02 0.40 0 0 0</pose>
      <axis>
        <xyz>0 1 0</xyz>
        <limit>
          <lower>-2.66162710929</lower>
          <upper>2.66162710929</upper>
          <effort>90.0</effort>
          <velocity>8.72664625997</velocity>
        </limit>
        <dynamics>
          <damping>0.6</damping>
          <friction>0.06</friction>
        </dynamics>
      </axis>
    </joint>

    <joint name="joint_4" type="revolute">
      <parent>link_3</parent>
      <child>link_4</child>
      <pose relative_to="link_3">0 0 0 0 0 0</pose>
      <axis>
        <xyz>0 0 1</xyz>
        <limit>
          <lower>-4.71238898038</lower>
          <upper>4.71238898038</upper>
          <effort>7.0</effort>
          <velocity>17.3664683405</velocity>
        </limit>
        <dynamics>
          <damping>0.8</damping>
          <friction>0.10</friction>
        </dynamics>
      </axis>
    </joint>

    <joint name="joint_5" type="revolute">
      <parent>link_4</parent>
      <child>link_5</child>
      <pose relative_to="link_4">0 0 0.45 0 0 0</pose>
      <axis>
        <xyz>0 1 0</xyz>
        <limit>
          <lower>-2.11184839491</lower>
          <upper>2.31256125889</upper>
          <effort>8.0</effort>
          <velocity>18.5875365032</velocity>
        </limit>
        <dynamics>
          <damping>0.6</damping>
          <friction>0.08</friction>
        </dynamics>
      </axis>
    </joint>

    <joint name="joint_6" type="revolute">
      <parent>link_5</parent>
      <child>link_6</child>
      <pose relative_to="link_5">0 0 0.07 0 0 0</pose>
      <axis>
        <xyz>0 0 1</xyz>
        <limit>
          <lower>-4.71238898038</lower>
          <upper>4.71238898038</upper>
          <effort>2.0</effort>
          <velocity>25.2201963626</velocity>
        </limit>
        <dynamics>
          <damping>0.5</damping>
          <friction>0.06</friction>
        </dynamics>
      </axis>
    </joint>

    <joint name="joint_6_flange" type="fixed">
      <parent>link_6</parent>
      <child>flange</child>
      <pose relative_to="link_6">0 0 0 0 -1.57079632679 0</pose>
    </joint>

    <joint name="base_link_base" type="fixed">
      <parent>base_link</parent>
      <child>base</child>
      <pose relative_to="base_link">0 0 0.375 0 0 0</pose>
    </joint>

    <joint name="flange_tool0" type="fixed">
      <parent>flange</parent>
      <child>tool0</child>
      <pose relative_to="flange">0 0 0 0 1.57079632679 0</pose>
    </joint>

    <joint name="tool0_gripper_base" type="fixed">
      <parent>tool0</parent>
      <child>gripper_base</child>
      <pose relative_to="tool0">0 0 0.035 0 0 0</pose>
    </joint>

    <joint name="gripper_left_finger_joint" type="prismatic">
      <parent>gripper_base</parent>
      <child>gripper_left_finger</child>
      <pose relative_to="gripper_base">0 0.047 0.045 0 0 0</pose>
      <axis>
        <xyz>0 1 0</xyz>
        <limit>
          <lower>0.0</lower>
          <upper>0.028</upper>
          <effort>20.0</effort>
          <velocity>0.05</velocity>
        </limit>
        <dynamics>
          <damping>0.2</damping>
          <friction>0.02</friction>
        </dynamics>
      </axis>
    </joint>

    <joint name="gripper_right_finger_joint" type="prismatic">
      <parent>gripper_base</parent>
      <child>gripper_right_finger</child>
      <pose relative_to="gripper_base">0 -0.047 0.045 0 0 0</pose>
      <axis>
        <xyz>0 -1 0</xyz>
        <limit>
          <lower>0.0</lower>
          <upper>0.028</upper>
          <effort>20.0</effort>
          <velocity>0.05</velocity>
        </limit>
        <dynamics>
          <damping>0.2</damping>
          <friction>0.02</friction>
        </dynamics>
      </axis>
    </joint>

    <joint name="gripper_base_tcp" type="fixed">
      <parent>gripper_base</parent>
      <child>gripper_tcp</child>
      <pose relative_to="gripper_base">0 0 0.060 0 0 0</pose>
    </joint>

    <plugin
      filename="gz-sim-joint-state-publisher-system"
      name="gz::sim::systems::JointStatePublisher">
      <joint_name>joint_1</joint_name>
      <joint_name>joint_2</joint_name>
      <joint_name>joint_3</joint_name>
      <joint_name>joint_4</joint_name>
      <joint_name>joint_5</joint_name>
      <joint_name>joint_6</joint_name>
      <joint_name>gripper_left_finger_joint</joint_name>
      <joint_name>gripper_right_finger_joint</joint_name>
    </plugin>

    <plugin
      filename="gz-sim-joint-trajectory-controller-system"
      name="gz::sim::systems::JointTrajectoryController">
      <!-- Integral limits must exceed the gravity torque of each joint,
           otherwise the arm sags below the commanded trajectory
           (~0.13 rad on joint_2, i.e. ~12 cm at the tool). -->
      <joint_name>joint_1</joint_name>
      <initial_position>0.0</initial_position>
      <position_p_gain>400.0</position_p_gain>
      <position_i_gain>10.0</position_i_gain>
      <position_d_gain>50.0</position_d_gain>
      <position_i_min>-50.0</position_i_min>
      <position_i_max>50.0</position_i_max>
      <position_cmd_min>-320.0</position_cmd_min>
      <position_cmd_max>320.0</position_cmd_max>

      <joint_name>joint_2</joint_name>
      <initial_position>0.0</initial_position>
      <position_p_gain>600.0</position_p_gain>
      <position_i_gain>20.0</position_i_gain>
      <position_d_gain>60.0</position_d_gain>
      <position_i_min>-100.0</position_i_min>
      <position_i_max>100.0</position_i_max>
      <position_cmd_min>-340.0</position_cmd_min>
      <position_cmd_max>340.0</position_cmd_max>

      <joint_name>joint_3</joint_name>
      <initial_position>0.0</initial_position>
      <position_p_gain>400.0</position_p_gain>
      <position_i_gain>15.0</position_i_gain>
      <position_d_gain>40.0</position_d_gain>
      <position_i_min>-60.0</position_i_min>
      <position_i_max>60.0</position_i_max>
      <position_cmd_min>-220.0</position_cmd_min>
      <position_cmd_max>220.0</position_cmd_max>

      <joint_name>joint_4</joint_name>
      <initial_position>0.0</initial_position>
      <position_p_gain>120.0</position_p_gain>
      <position_i_gain>4.0</position_i_gain>
      <position_d_gain>16.0</position_d_gain>
      <position_i_min>-20.0</position_i_min>
      <position_i_max>20.0</position_i_max>
      <position_cmd_min>-90.0</position_cmd_min>
      <position_cmd_max>90.0</position_cmd_max>

      <joint_name>joint_5</joint_name>
      <initial_position>0.0</initial_position>
      <position_p_gain>100.0</position_p_gain>
      <position_i_gain>4.0</position_i_gain>
      <position_d_gain>12.0</position_d_gain>
      <position_i_min>-20.0</position_i_min>
      <position_i_max>20.0</position_i_max>
      <position_cmd_min>-70.0</position_cmd_min>
      <position_cmd_max>70.0</position_cmd_max>

      <joint_name>joint_6</joint_name>
      <initial_position>0.0</initial_position>
      <position_p_gain>80.0</position_p_gain>
      <position_i_gain>2.0</position_i_gain>
      <position_d_gain>10.0</position_d_gain>
      <position_i_min>-10.0</position_i_min>
      <position_i_max>10.0</position_i_max>
      <position_cmd_min>-60.0</position_cmd_min>
      <position_cmd_max>60.0</position_cmd_max>
    </plugin>

    <plugin
      filename="gz-sim-joint-trajectory-controller-system"
      name="gz::sim::systems::JointTrajectoryController">
      <topic>/staubli1/gripper_joint_trajectory</topic>

      <joint_name>gripper_left_finger_joint</joint_name>
      <initial_position>0.028</initial_position>
      <position_p_gain>180.0</position_p_gain>
      <position_i_gain>0.0</position_i_gain>
      <position_d_gain>8.0</position_d_gain>
      <position_cmd_min>-25.0</position_cmd_min>
      <position_cmd_max>25.0</position_cmd_max>

      <joint_name>gripper_right_finger_joint</joint_name>
      <initial_position>0.028</initial_position>
      <position_p_gain>180.0</position_p_gain>
      <position_i_gain>0.0</position_i_gain>
      <position_d_gain>8.0</position_d_gain>
      <position_cmd_min>-25.0</position_cmd_min>
      <position_cmd_max>25.0</position_cmd_max>
    </plugin>
  </model>
</sdf>
